<?xml version="1.0" encoding="utf-8"?>
<!-- This URDF was automatically created by SolidWorks to URDF Exporter! Originally created by Stephen Brawner (brawner@gmail.com) 
     Commit Version: 1.6.0-4-g7f85cfe  Build Version: 1.6.7995.38578
     For more information, please see http://wiki.ros.org/sw_urdf_exporter -->
<robot
  name="my_robot">
  <link
    name="base_link">
    <inertial>
      <origin
        xyz="0.0444584205913184 4.24664789892465E-07 0.290941387979721"
        rpy="0 0 0" />
      <mass
        value="24.8695679911603" />
      <inertia
        ixx="0.801673252330792"
        ixy="3.47520793982699E-06"
        ixz="-0.00190246392947462"
        iyy="0.760171269691538"
        iyz="-3.33361889772832E-06"
        izz="1.06129416759769" />
    </inertial>
    <visual>
      <origin
        xyz="0 0 0"
        rpy="0 0 0" />
      <geometry>
        <mesh
          filename="file:///home/tarek/ros_ws/src/my_robot/meshes/base_link.STL" />
      </geometry>
      <material
        name="">
        <color
          rgba="0.0 0.0 0.8 1" />
      </material>
      
    </visual>
    <collision>
      <origin
        xyz="0 0 0"
        rpy="0 0 0" />
      <geometry>
        <mesh
          filename="file:///home/tarek/ros_ws/src/my_robot/meshes/base_link.STL" />
      </geometry>
    </collision>
  </link>
  
        
 <link name="caster1">
    <visual>
      <geometry><sphere radius="0.0145"/></geometry>
      <material name="white"><color rgba="1 1 1 1"/></material>
    </visual>
    <collision>
      <geometry><sphere radius="0.0145"/></geometry>
    </collision>
    <inertial>
      <mass value="0.1"/>
      <inertia ixx="0.0000084" ixy="0" ixz="0" iyy="0.0000084" iyz="0" izz="0.0000084"/>
    </inertial>
  </link>

  <gazebo reference="caster1">
    <mu1>0.001</mu1>
    <mu2>0.001</mu2>
    <kp>1000000.0</kp>
    <kd>1.0</kd>
  </gazebo>

  <joint name="caster1_j" type="fixed"> <parent link="base_link"/><child link="caster1"/>
    <origin xyz="0.1362 -0.1502 -0.0165" rpy="0 0 0"/>
  </joint>

  <link name="caster2">
    <visual>
      <geometry><sphere radius="0.0145"/></geometry>
      <material name="white"/>
    </visual>
    <collision>
      <geometry><sphere radius="0.0145"/></geometry>
    </collision>
    <inertial>
      <mass value="0.1"/>
      <inertia ixx="0.0000084" ixy="0" ixz="0" iyy="0.0000084" iyz="0" izz="0.0000084"/>
    </inertial>
  </link>
  <gazebo reference="caster2">
    <mu1>0.001</mu1>
    <mu2>0.001</mu2>
  </gazebo>
  <joint name="caster2_j" type="fixed">
    <parent link="base_link"/><child link="caster2"/>
    <origin xyz="0.1362 0.1497 -0.0165" rpy="0 0 0"/>
  </joint>

  <link name="caster3">
    <visual>
      <geometry><sphere radius="0.0145"/></geometry>
      <material name="white"/>
    </visual>
    <collision>
      <geometry><sphere radius="0.0145"/></geometry>
    </collision>
    <inertial>
      <mass value="0.1"/>
      <inertia ixx="0.0000084" ixy="0" ixz="0" iyy="0.0000084" iyz="0" izz="0.0000084"/>
    </inertial>
  </link>
  <gazebo reference="caster3">
    <mu1>0.001</mu1>
    <mu2>0.001</mu2>
  </gazebo>
  <joint name="caster3_j" type="fixed">
    <parent link="base_link"/><child link="caster3"/>
    <origin xyz="-0.1362 -0.1497 -0.0165" rpy="0 0 0"/>
  </joint>

  <link name="caster4">
    <visual>
      <geometry><sphere radius="0.0145"/></geometry>
      <material name="white"/>
    </visual>
    <collision>
      <geometry><sphere radius="0.0145"/></geometry>
    </collision>
    <inertial>
      <mass value="0.1"/>
      <inertia ixx="0.0000084" ixy="0" ixz="0" iyy="0.0000084" iyz="0" izz="0.0000084"/>
    </inertial>
  </link>
  <gazebo reference="caster4">
    <mu1>0.001</mu1>
    <mu2>0.001</mu2>
  </gazebo>
  <joint name="caster4_j" type="fixed">
    <parent link="base_link"/><child link="caster4"/>
    <origin xyz="-0.1362 0.1502 -0.0165" rpy="0 0 0"/>
  </joint>
  <link name="rw">
    <inertial>
      <origin
        xyz="-1.39650217168128E-06 -1.74443973384973E-05 -0.0262826021889727"
        rpy="0 0 0" />
      <mass
        value="0.417517803921102" />
      <inertia
        ixx="0.000400381828676672"
        ixy="2.91619672856075E-09"
        ixz="-2.72392571239969E-08"
        iyy="0.000400418022873573"
        iyz="-3.40258994317761E-07"
        izz="0.000664107599905788" />
    </inertial>
    
    <visual>
      <origin xyz="0 0 0" rpy="0 0 0" />
      <geometry>
        <mesh filename="file:///home/tarek/ros_ws/src/my_robot/meshes/rw.STL" />
      </geometry>
      <material name="">
        <color rgba="0.2 0.2 0.2 1" />
      </material>
    </visual>
    
    <collision>
      <origin xyz="0 0 0" rpy="0 0 0" />
      <geometry>
        <mesh filename="file:///home/tarek/ros_ws/src/my_robot/meshes/rw.STL" />
      </geometry>
    </collision>
  </link>

  <gazebo reference="rw">
    <mu1>1.5</mu1>       <mu2>1.5</mu2>
    <kp>1000000.0</kp>   <kd>1.0</kd>         <material>Gazebo/DarkGrey</material>
  </gazebo>

  <joint name="rj" type="continuous">
    <origin
      xyz="0 -0.1765 0.025"
      rpy="1.5708 0 0" />
    <parent link="base_link" />
    <child link="rw" />
    <axis xyz="0 0 -1" />
    
    <limit effort="1000.0" velocity="20.0"/> <dynamics damping="0.1" friction="0.1"/>
  </joint>
  <link name="lw">
    <inertial>
      <origin
        xyz="-1.39650217423423E-06 -1.74443973382822E-05 0.0262826021889727"
        rpy="0 0 0" />
      <mass
        value="0.417517803921102" />
      <inertia
        ixx="0.000400381828676672"
        ixy="2.9161967286292E-09"
        ixz="2.72392571256925E-08"
        iyy="0.000400418022873573"
        iyz="3.40258994317754E-07"
        izz="0.000664107599905788" />
    </inertial>
    
    <visual>
      <origin xyz="0 0 0" rpy="0 0 0" />
      <geometry>
        <mesh filename="file:///home/tarek/ros_ws/src/my_robot/meshes/lw.STL" />
      </geometry>
      <material name="">
        <color rgba="0.2 0.2 0.2 1" />
      </material>
    </visual>
    
    <collision>
      <origin xyz="0 0 0" rpy="0 0 0" />
      <geometry>
        <mesh filename="file:///home/tarek/ros_ws/src/my_robot/meshes/lw.STL" />
      </geometry>
    </collision>
  </link>

  <gazebo reference="lw">
    <mu1>1.5</mu1>
    <mu2>1.5</mu2>
    <kp>1000000.0</kp>
    <kd>1.0</kd>
    <material>Gazebo/DarkGrey</material>
  </gazebo>

  <joint name="lj" type="continuous">
    <origin
      xyz="0 0.1765 0.025"
      rpy="1.5708 0 0" />
    <parent link="base_link" />
    <child link="lw" />
    
    <axis xyz="0 0 -1" />
    
    <limit effort="1000.0" velocity="20.0"/>
    <dynamics damping="0.1" friction="0.1"/>
  </joint>

 


<!-- Gazebo Plugins -->
<gazebo>
    <plugin filename="gz-sim-sensors-system"
          name="gz::sim::systems::Sensors">
    <render_engine>ogre2</render_engine>
  </plugin>
    <plugin filename="gz_ros2_control-system" name="gz_ros2_control::GazeboSimROS2ControlPlugin">
        <parameters>/home/tarek/ros_ws/src/my_robot/config/controllers.yaml</parameters>
    </plugin>
  </gazebo>

  <ros2_control name="GazeboSimSystem" type="system">
  <hardware>
    <plugin>gz_ros2_control/GazeboSimSystem</plugin>
  </hardware>
  
  <joint name="rj"> 
    <command_interface name="velocity">
      <param name="min">-10</param>
      <param name="max">10</param>
    </command_interface>
    <state_interface name="velocity"/>
    <state_interface name="position"/>
  </joint>

  <joint name="lj">
    <command_interface name="velocity">
      <param name="min">-10</param>
      <param name="max">10</param>
    </command_interface>
    <state_interface name="velocity"/>
    <state_interface name="position"/>
  </joint>
</ros2_control>



 <link name="lidar_link">
  <visual>
    <geometry>
      <cylinder radius="0.038" length="0.03"/>
    </geometry>
    <material name="black">
      <color rgba="0 0 0 1"/>
    </material>
  </visual>
  <collision>
    <geometry>
      <cylinder radius="0.038" length="0.03"/>
    </geometry>
  </collision>
  <inertial>
    <mass
        value="0.16539872952342" />

    <inertia ixx="0.0001" iyy="0.0001" izz="0.0001" ixy="0" ixz="0" iyz="0"/>
  </inertial>
</link>


<joint name="lidar_joint" type="fixed">
  <parent link="base_link"/>
  <child link="lidar_link"/>
  <origin xyz="0.215 0 0.23" rpy="0 0 0"/>
</joint>

<gazebo reference="lidar_link">
  <pose>0 0 0 0 0 0</pose>
  <sensor name="lidar" type="gpu_ray">
    <always_on>true</always_on>
    <visualize>true</visualize>
    <topic>/scan</topic>
    <update_rate>5</update_rate>
    <gz_frame_id>lidar_link</gz_frame_id>
    <ray>
      <scan>
        <horizontal>
          <samples>360</samples>
          <resolution>1</resolution>
          <min_angle>-3.14</min_angle>
          <max_angle>3.14</max_angle>
        </horizontal>
      </scan>
      <range>
        <min>0.6</min>
        <max>15.0</max>
        <resolution>0.02</resolution>
      </range>
      <noise>
        <type>gaussian</type>
        <mean>0.0</mean>
        <stddev>0.01</stddev>
      </noise>
    </ray>
  </sensor>
</gazebo>





</robot>